Workbook

Sheet Output comparison
J3: €/USD
J4: 0.85
C5: Conversion factor | D5: eSMR | E5: SMR | G5: conservative | H5: Base-scenario | I5: optimistic
B7: Hydrogen, m3 (STP/h) | D7: ='OCMC eSMR'!AY34 -> 5000.5 | E7: ='SMR, WGSR, C-forming, C2H6'!AS34 -> 5000.5 | Q7: eSMR | T7: SMR
B8: Natural gas, MWh/h | C8: =36.6*0.000277778 -> 0.010166675 | D8: =-'OCMC eSMR'!D34*C8 -> -13.90249 | E8: =-'SMR, WGSR, C-forming, C2H6'!D34*C8 -> -21.960018 | G8: 15 | H8: 40 | I8: 40 | J8: €/MWh | K8: USA | L8: https://www.intratec.us/solutions/energy-prices-markets/commodity/natural-gas-price-united-states | M8: Germany | N8: https://www.intratec.us/solutions/energy-prices-markets/commodity/natural-gas-price-germany | O8: China | P8: https://www.intratec.us/solutions/energy-prices-markets/commodity/natural-gas-price-china | Q8: =$D8*G8 -> -208.53735 | R8: =$D8*H8 -> -556.0996 | S8: =$D8*I8 -> -556.0996 | T8: =$E8*G8 -> -329.40026 | U8: =$E8*H8 -> -878.4007 | V8: =$E8*I8 -> -878.4007
B9: MP steam, kg/h | D9: 0 | E9: ='SMR, WGSR, C-forming, C2H6'!V3 -> 985.86697 | G9: =G8*0.95*'OCMC eSMR'!$P$14*0.000000277778 -> 0.012199989 | H9: =H8*0.95*'OCMC eSMR'!$P$14*0.000000277778 -> 0.032533304 | I9: =I8*0.95*'OCMC eSMR'!$P$14*0.000000277778 -> 0.032533304 | J9: €/kg | Q9: =$D9*G9 -> 0 | R9: =$D9*H9 -> 0 | S9: =$D9*I9 -> 0 | T9: =$E9*G9 -> 12.027566 | U9: =$E9*H9 -> 32.07351 | V9: =$E9*I9 -> 32.07351
B10: Electricity, kWh/h | C10: 0.000277778 | D10: =-'OCMC eSMR'!AA45*C10 -> -3496.9106 | E10: 0 | G10: 0.18 | H10: 0.4 | I10: 0.08 | J10: $/kWh | K10: USA | L10: Germany | M10: China/India | N10: https://worldpopulationreview.com/country-rankings/cost-of-electricity-by-country | Q10: =$D10*G10*$J$4 -> -535.02731 | R10: =$D10*H10*$J$4 -> -1188.9496 | S10: =$D10*I10*$J$4 -> -237.78992 | T10: =$E10*G10*$J$4 -> 0 | U10: =$E10*H10*$J$4 -> 0 | V10: =$E10*I10*$J$4 -> 0
B11: Water, kg/h | D11: 0 | E11: =-'SMR, WGSR, C-forming, C2H6'!AJ17 -> -4700 | G11: =3/1000 -> 0.003 | H11: =4/1000 -> 0.004 | I11: =5/1000 -> 0.005 | J11: €/kg | K11: https://www.zfk.de/wasser-abwasser/wasser/industriewasser-wird-im-schnitt-ein-cent-teurer | Q11: =$D11*G11 -> 0 | R11: =$D11*H11 -> 0 | S11: =$D11*I11 -> 0 | T11: =$E11*G11 -> -14.1 | U11: =$E11*H11 -> -18.8 | V11: =$E11*I11 -> -23.5
B12: Waste water, kg/h | D12: ='OCMC eSMR'!AP19 -> 1459.9683 | E12: ='SMR, WGSR, C-forming, C2H6'!AP17 -> 2139.6529 | G12: =-4/1000 -> -0.004 | H12: =-8/1000 -> -0.008 | I12: =-12/1000 -> -0.012 | J12: $/kg | K12: https://porvoo.com.cn/blog/wastewater-treatment-prices-investment-breakdown/ | L12: https://www.sciencedirect.com/science/article/pii/S0921344919305695 | Q12: =$D12*G12*$J$4 -> -4.9638921 | R12: =$D12*H12*$J$4 -> -9.9277841 | S12: =$D12*I12*$J$4 -> -14.891676 | T12: =$E12*G12*$J$4 -> -7.2748197 | U12: =$E12*H12*$J$4 -> -14.549639 | V12: =$E12*I12*$J$4 -> -21.824459
B13: CO2 concentrated, kg/h | D13: ='OCMC eSMR'!AU9 -> 2083.2491 | E13: 0 | G13: =-30/1000 -> -0.03 | H13: =-21/1000 -> -0.021 | I13: =-12/1000 -> -0.012 | J13: $/kg | K13: CCS | L13: https://zeroemissionsplatform.eu/publication/co2-storage-cost/ | M13: https://www.sciencedirect.com/science/article/pii/S1750583621001195 | N13: https://www.globalccsinstitute.com/wp-content/uploads/2025/12/Cost-of-CO2-Storage-1225.pdf | O13: CCU | P13: https://businessanalytiq.com/procurementanalytics/index/carbon-dioxide-price-index/ | Q13: =$D13*G13*$J$4 -> -53.122853 | R13: =$D13*H13*$J$4 -> -37.185997 | S13: =$D13*I13*$J$4 -> -21.249141 | T13: =$E13*G13*$J$4 -> 0 | U13: =$E13*H13*$J$4 -> 0 | V13: =$E13*I13*$J$4 -> 0
B14: CO2 emitted, kg/h | D14: =SUM('OCMC eSMR'!AZ61:AZ63) -> 368.74809 | E14: ='SMR, WGSR, C-forming, C2H6'!AC5 -> 3976.4973 | G14: 0 | H14: =-80/1000 -> -0.08 | I14: =-2.27/1000 -> -0.00227 | J14: €/kg | K14: https://tradingeconomics.com/commodity/carbon | Q14: =$D14*G14 -> 0 | R14: =$D14*H14 -> -29.499847 | S14: =$D14*I14 -> -0.83705816 | T14: =$E14*G14 -> 0 | U14: =$E14*H14 -> -318.11979 | V14: =$E14*I14 -> -9.0266489
C15: https://www.engineeringtoolbox.com/fuels-higher-calorific-values-d_169.html | Q15: =SUM(Q8:Q14) -> -801.65141 | R15: =SUM(R8:R14) -> -1821.6628 | S15: =SUM(S8:S14) -> -830.86739 | T15: =SUM(T8:T14) -> -338.74752 | U15: =SUM(U8:U14) -> -1197.7966 | V15: =SUM(V8:V14) -> -900.6783
U20: ratios
U21: N2/electricity
U22: CO2 tax/electricity
U23: Eingesparte tonne CO2 pro MWh Strom
I25: 87 | J25: CNY/MMBtu | K25: 0.29 | L25: MWh/MMBtu | M25: 0.13 | N25: €/CNY | O25: =I25/K25*M25 -> 39
G26: 5 | H26: USD/MMBtu | I26: 0.29 | J26: MWh/MMBtu | K26: 0.85 | L26: €/USD | M26: =G26/I26*K26 -> 14.655172

Sheet OCMC eSMR
F1: Parameter | G1: Feed, 1 | H1: Before desulfurization, 2 | I1: Reformer inlet, 3 | J1: Reformer outlet, 4 | K1: Pressure swing adsorption, 5 | L1: H2 product, 6
F2: H2, vol % | G2: 0 | H2: 4.8 | I2: 1.1 | J2: 51.9 | K2: 74.6 | L2: 99.99
F3: N2, vol % | G3: 1 | H3: 1 | I3: 0.3 | J3: 0.2 | K3: 0.25 | L3: 0.01
F4: CO, vol % | G4: 0 | H4: 0 | I4: 0 | J4: 10.7 | K4: 5.3 | L4: 0 | AN4: id Gas
F5: CO2, vol % | G5: 0.5 | H5: 0.5 | I5: 0.1 | J5: 5.1 | K5: 14.8 | L5: 0 | AN5: Henry-coefficient | AO5: S_(i/CO2)=H_CO2/H_i | AP5: p_i/p_CO2 | AQ5: n_i=n_CO2*(p_i/p_CO2)*S_(i/CO2) | AR5: Parameter | AS5: CO2 for CCU | AT5: Mole, mol | AU5: Mass flow, kg/h
F6: CH4, vol % | G6: 95 | H6: 90.4 | I6: 26.1 | J6: 3.8 | K6: 4.9 | L6: 0 | AN6: 626 | AO6: =$AN$9/AN6 -> 0.0079872204 | AP6: =AQ27/$AQ$30 -> 4.7907332 | AQ6: =$AT$9*AO6*AP6 -> 1811.6996 | AR6: H2, vol % | AS6: =AT6/$AT$13*100 -> 3.5844871 | AT6: =AQ6 -> 1811.6996
F7: C2+, vol % | G7: 3.5 | H7: 3.3 | I7: 1 | J7: 0 | K7: 0 | L7: 0 | AN7: 364 | AO7: =$AN$9/AN7 -> 0.013736264 | AP7: =AQ28/$AQ$30 -> 0.050140283 | AQ7: =$AT$9*AO7*AP7 -> 32.609485 | AR7: N2, vol % | AS7: =AT7/$AT$13*100 -> 0.064518576 | AT7: =AQ7 -> 32.609485
F8: H2O, vol % | G8: 0 | H8: 0 | I8: 71.4 | J8: 28.3 | K8: 0.15 | L8: 0 | AN8: 239 | AO8: =$AN$9/AN8 -> 0.020920502 | AP8: =AQ29/$AQ$30 -> 0.67961032 | AQ8: =$AT$9*AO8*AP8 -> 673.16357 | AR8: CO, vol % | AS8: =AT8/$AT$13*100 -> 1.3318688 | AT8: =AQ8 -> 673.16357
F9: Quantity, m3 (STP/h) | G9: 2160 | H9: 2070 | I9: 7160 | J9: 10450 | K9: 8180 | L9: 5000.5 | AN9: 5 | AO9: =$AN$9/AN9 -> 1 | AP9: =AQ30/$AQ$30 -> 1 | AQ9: =$AT$9*AO9*AP9 -> 47346.571 | AR9: CO2, vol % | AS9: =AT9/$AT$13*100 -> 93.676223 | AT9: =AQ30-AV30 -> 47346.571 | AU9: =AT9*44/1000 -> 2083.2491
F10: Temperature, °C | G10: 20 | H10: 390 | I10: 520 | J10: 850 | K10: 20 | L10: 20 | AN10: 91.8 | AO10: =$AN$9/AN10 -> 0.054466231 | AP10: =AQ31/$AQ$30 -> 0.06468899 | AQ10: =$AT$9*AO10*AP10 -> 166.81927 | AR10: CH4, vol % | AS10: =AT10/$AT$13*100 -> 0.33005557 | AT10: =AQ10 -> 166.81927
F11: Pressure, MPa | G11: 2 | H11: 1.9 | I11: 1.9 | J11: 1.7 | K11: 1.6 | L11: 1.5 | AN11: 10.25 | AO11: =$AN$9/AN11 -> 0.48780488 | AP11: =AQ32/$AQ$30 -> 0 | AQ11: =$AT$9*AO11*AP11 -> 0 | AR11: C2+, vol % | AS11: =AT11/$AT$13*100 -> 0 | AT11: =AQ11 -> 0
P12: isenthalpic | AR12: H2O, vol % | AS12: =AT12/$AT$13*100 -> 1.0128473 | AT12: =AQ33 -> 511.92124
N13: Parameter | O13: HP reforming steam import | P13: From water to steam | Q13: Mole, mol | R13: Mass flow, kg/h | S13: Energy, kJ/h | AR13: Quantity, m3 (STP/h) | AS13: =AT13*$E$24*$B$34/$A$34/1000 -> 1252.2339 | AT13: =SUM(AT6:AT12) -> 50542.785
N14: Energy, kJ/kg | O14: 3166.1 | P14: =3166.1-84 -> 3082.1 | T14: https://www.peacesoftware.de/einigewerte/wasser_dampf.html | AR14: Temperature, °C | AS14: 20
N15: H2O, vol % | O15: 100 | Q15: =T33-L33 -> 147111.23 | R15: =Q15*18/1000 -> 2648.0021 | S15: =P14*R15 -> 8161407.1 | AR15: Pressure, MPa | AS15: 0.1
N16: Quantity, m3 (STP/h) | O16: =Q15*$E$24*$B$34/$A$34/1000 -> 3644.7865
N17: Temperature, °C | O17: 390 | P17: 390 | AM17: Parameter | AN17: Waste water | AO17: Mole, mol | AP17: Mass flow, kg/h
N18: Pressure, MPa | O18: 5.3 | P18: 5.3 | AM18: Specific enthalpy, kJ/kg | AN18: 84
AM19: H2O, vol % | AN19: 100 | AO19: =AC33-AQ33 -> 81109.348 | AP19: =AO19*18/1000 -> 1459.9683 | AQ19: =AN18*AP19 -> 122637.33
M20: S/C | AM20: Temperature, °C | AN20: 20 | AO20: https://www.peacesoftware.de/einigewerte/wasser_dampf.html
M21: 2.5 | AM21: Pressure, MPa | AN21: 0.1
AH22: T_in | AI22: T_out
E23: R | AD23: T_out HXI | AH23: 313.89263 | AI23: 440 | AR23: 1 – 2 % can even be reached in the main wash part with just ﬂash-regenerated methanol. Therefore external energy input is neglected as first simplification | AV23: 0.82 | AW23: H2 recovery
E24: 0.08314 | AD24: =S35 -> 520
C26: Parameter | D26: Feed, 1 | E26: Mole, mol | G26: Molar heat capacity, kJ/mol | H26: Heat-up energy, kJ/h | J26: Parameter | K26: Before desulfurization, 2 | L26: Mole, mol | O26: Molar heat capacity, kJ/mol | P26: Heat-up energy, kJ/h | R26: Parameter | S26: Reformer inlet, 3 | T26: Mole, mol | U26: Molar heat capacity, kJ/mol | V26: Heat-up energy, kJ/h | W26: Reaction number | X26: Reaction enthalpy, kJ/h | Y26: Insulation losses, kJ | AA26: Parameter | AB26: Reformer outlet, 4 | AC26: Mole, mol | AD26: Molar heat capacity, kJ/mol | AE26: Heat-down energy, kJ/h | AF26: Molar heat capacity, kJ/mol | AG26: Heat-down energy, kJ/h | AK26: Molar heat capacity, kJ/mol | AL26: Heat-down energy, kJ/h | AO26: Parameter | AP26: Pressure swing adsorption, 5 | AQ26: Mole, mol | AT26: Parameter | AU26: Pressure swing adsorption, 5 | AV26: Mole, mol | AX26: Parameter | AY26: H2 product, 6 | AZ26: Mole, mol
C27: H2, vol % | D27: 0 | E27: =($A$34)*($D$34*D27/100*1000)/($E$24*$B$34) -> 0 | G27: {=N91:N97} -> 11.412697 | H27: =G27*L27 -> 404777.26 | J27: H2, vol % | K27: =L27/$L$34*100 -> 28.061119 | L27: =E27+AI58 -> 35467.276 | O27: {=N99:N105} -> 3.9119754 | P27: =T27*O27 -> 138747.11 | R27: H2, vol % | S27: =T27/$T$34*100 -> 12.967727 | T27: =L27 -> 35467.276 | U27: {=N107:N113} -> 17.899022 | V27: =T27*U27 -> 634829.56 | W27: I | X27: =Z108*AC121 -> 12040545 | Y27: min | AA27: H2, vol % | AB27: 54.6059 | AC27: =AB27/100*$AC$34 -> 209963.62 | AD27: {=N115:N121} -> -17.899022 | AE27: =AC27*AD27 -> -3758143.6 | AF27: {=N123:N129} -> -6.2076423 | AG27: =AC27*AF27 -> -1303379.1 | AK27: {=N131:N137} -> -12.917366 | AL27: =AK27*AV27 -> -3178947.2 | AO27: H2, vol % | AP27: =AQ27/$AQ$34*100 -> 72.641178 | AQ27: =AC27+AC29*AH29 -> 247910.41 | AT27: H2, vol % | AU27: =AV27/$AV$34*100 -> 84.646203 | AV27: =AQ27-AT6 -> 246098.71 | AX27: H2, vol % | AY27: 99.99 | AZ27: =AY27/100*$AZ$34 -> 201810.48 | BA27: =AZ27/AV27 -> 0.82003874
C28: N2, vol % | D28: 1 | E28: =($A$34)*($D$34*D28/100*1000)/($E$24*$B$34) -> 551.93428 | G28: 9.0299095 | H28: =G28*L28 -> 23365.142 | J28: N2, vol % | K28: =L28/$L$34*100 -> 2.047209 | L28: =E28+AI59 -> 2587.5278 | O28: 3.7626703 | P28: =T28*O28 -> 9736.0143 | R28: N2, vol % | S28: =T28/$T$34*100 -> 0.9460652 | T28: =L28 -> 2587.5278 | U28: 18.616532 | V28: =T28*U28 -> 48170.796 | W28: IV | X28: =Z107*AC126 -> -286012.52 | Y28: 0.01 | AA28: N2, vol % | AB28: 0.6748 | AC28: =AB28/100*$AC$34 -> 2594.6547 | AD28: -18.616532 | AE28: =AC28*AD28 -> -48303.473 | AF28: -5.8595386 | AG28: =AC28*AF28 -> -15203.479 | AK28: -10.452252 | AL28: =AK28*AV28 -> -26779.141 | AO28: N2, vol % | AP28: =AQ28/$AQ$34*100 -> 0.76026969 | AQ28: =AC28 -> 2594.6547 | AT28: N2, vol % | AU28: =AV28/$AV$34*100 -> 0.88122118 | AV28: =AQ28-AT7 -> 2562.0452 | AX28: N2, vol % | AY28: 0.01 | AZ28: =AY28/100*$AZ$34 -> 20.183066
C29: CO, vol % | D29: 0 | E29: =($A$34)*($D$34*D29/100*1000)/($E$24*$B$34) -> 0 | G29: 10.524394 | H29: =G29*L29 -> 290733.74 | J29: CO, vol % | K29: =L29/$L$34*100 -> 21.856242 | L29: =E29+AI60 -> 27624.749 | O29: 4.0133733 | P29: =T29*O29 -> 110868.43 | R29: CO, vol % | S29: =T29/$T$34*100 -> 10.100303 | T29: =L29 -> 27624.749 | U29: 19.303674 | V29: =T29*U29 -> 533259.15 | W29: VII | X29: not relevant | Y29: max | AA29: CO, vol % | AB29: 19.0153 | AC29: =AB29/100*$AC$34 -> 73115.2 | AD29: -19.303674 | AE29: =AC29*AD29 -> -1411392 | AF29: -6.2944433 | AG29: =AC29*AF29 -> -460219.48 | AH29: 0.519 | AI29: CO-conversion | AK29: -12.051072 | AL29: =AK29*AV29 -> -415704.72 | AO29: CO, vol % | AP29: =AQ29/$AQ$34*100 -> 10.304831 | AQ29: =AC29*(1-AH29) -> 35168.411 | AT29: CO, vol % | AU29: =AV29/$AV$34*100 -> 11.864718 | AV29: =AQ29-AT8 -> 34495.248 | AX29: CO, vol % | AY29: 0 | AZ29: =AY29/100*$AZ$34 -> 0
C30: CO2, vol % | D30: 0.5 | E30: =($A$34)*($D$34*D30/100*1000)/($E$24*$B$34) -> 275.96714 | G30: 16.648488 | H30: =G30*L30 -> 63275.544 | J30: CO2, vol % | K30: =L30/$L$34*100 -> 3.0070332 | L30: =E30+AI61 -> 3800.6781 | O30: 6.580752 | P30: =T30*O30 -> 25011.32 | R30: CO2, vol % | S30: =T30/$T$34*100 -> 1.3896234 | T30: =L30 -> 3800.6781 | U30: 32.044939 | V30: =T30*U30 -> 121792.5 | W30: VIII | X30: =Z109*AC135 -> 834335.5 | Y30: 0.05 | Z30: CH4 Umsatz | AA30: CO2, vol % | AB30: 3.5893 | AC30: =AB30/100*$AC$34 -> 13801.117 | AD30: -32.044939 | AE30: =AC30*AD30 -> -442255.97 | AF30: -10.280325 | AG30: =AC30*AF30 -> -141879.97 | AK30: -19.143103 | AL30: =AK30*AV30 -> -84255.209 | AO30: CO2, vol % | AP30: =AQ30/$AQ$34*100 -> 15.162852 | AQ30: =AC30+(AC29*AH29) -> 51747.906 | AS30: [Ullmann's, Gas Production, 3. Gas Treating, 504] | AT30: CO2, vol % | AU30: 1.5 | AV30: =SUM(AQ27:AQ29,AQ31:AQ32)/(1-(AU30/100))*(AU30/100) -> 4401.335 | AX30: CO2, vol % | AY30: 0 | AZ30: =AY30/100*$AZ$34 -> 0
B31: 74 | C31: CH4, vol % | D31: 95 | E31: =($A$34)*($D$34*D31/100*1000)/($E$24*$B$34) -> 52433.757 | G31: 14.130909 | H31: =G31*L31 -> 776930.81 | J31: CH4, vol % | K31: =L31/$L$34*100 -> 43.500013 | L31: =E31+AI62 -> 54980.95 | O31: 7.3660903 | P31: =T31*O31 -> 404994.64 | R31: CH4, vol % | S31: =T31/$T$34*100 -> 20.102417 | T31: =L31 -> 54980.95 | U31: 42.380994 | V31: =T31*U31 -> 2330147.3 | Y31: 1100°C | Z31: 0.948 | AA31: CH4, vol % | AB31: 0.8706 | AC31: =AB31/100*$AC$34 -> 3347.5198 | AD31: -42.380994 | AE31: =AC31*AD31 -> -141871.22 | AF31: -11.183194 | AG31: =AC31*AF31 -> -37435.963 | AK31: -16.844385 | AL31: =AK31*AV31 -> -53576.944 | AO31: CH4, vol % | AP31: =AQ31/$AQ$34*100 -> 0.98086958 | AQ31: =AC31 -> 3347.5198 | AT31: CH4, vol % | AU31: =AV31/$AV$34*100 -> 1.0940091 | AV31: =AQ31-AT10 -> 3180.7005 | AX31: CH4, vol % | AY31: 0 | AZ31: =AY31/100*$AZ$34 -> 0
C32: C2+, vol % | D32: 3.5 | E32: =($A$34)*($D$34*D32/100*1000)/($E$24*$B$34) -> 1931.77 | G32: 14.130909 | H32: =G32*L32 -> 27297.666 | J32: C2+, vol % | K32: =L32/$L$34*100 -> 1.5283843 | L32: =E32+AI63 -> 1931.77 | O32: 7.3660903 | P32: =T32*O32 -> 14229.592 | R32: C2+, vol % | S32: =T32/$T$34*100 -> 0.70630366 | T32: =L32 -> 1931.77 | U32: 42.380994 | V32: =T32*U32 -> 81870.333 | Y32: 0 | AA32: C2+, vol % | AB32: 0 | AC32: =AB32/100*$AC$34 -> 0 | AD32: -42.380994 | AE32: =AC32*AD32 -> 0 | AF32: -11.183194 | AG32: =AC32*AF32 -> 0 | AK32: -16.844385 | AL32: =AK32*AV32 -> 0 | AO32: C2+, vol % | AP32: =AQ32/$AQ$34*100 -> 0 | AQ32: =AC32 -> 0 | AT32: C2+, vol % | AU32: =AV32/$AV$34*100 -> 0 | AV32: =AQ32-AT11 -> 0 | AX32: C2+, vol % | AY32: 0 | AZ32: =AY32/100*$AZ$34 -> 0
A33: p_0 | B33: T_0 | C33: H2O, vol % | D33: 0 | E33: =($A$34)*($D$34*D33/100*1000)/($E$24*$B$34) -> 0 | G33: 12.671218 | H33: =G33*L33 -> 0 | J33: H2O, vol % | K33: =L33/$L$34*100 -> 0 | L33: =E33+AI64 -> 0 | O33: 4.8794395 | P33: =T33*O33 -> 717820.33 | R33: H2O, vol % | S33: =T33/$T$34*100 -> 53.787561 | T33: =(T31+2*T32)*M21 -> 147111.23 | U33: 24.432108 | V33: =T33*U33 -> 3594237.3 | Z33: mol_out/mol_in | AA33: H2O, vol % | AB33: 21.2275 | AC33: =AB33/100*$AC$34 -> 81621.269 | AD33: -24.432108 | AE33: =AC33*AD33 -> -1994179.6 | AF33: -7.6334962 | AG33: =AC33*AF33 -> -623055.65 | AK33: -14.521697 | AL33: =AK33*AV33 -> 0 | AO33: H2O, vol % | AP33: 0.15 | AQ33: =SUM(AQ27:AQ32)/(1-(AP33/100))*(AP33/100) -> 511.92124 | AT33: H2O, vol % | AU33: =AV33/$AV$34*100 -> 0 | AV33: =AQ33-AT12 -> 0 | AX33: H2O, vol % | AY33: 0 | AZ33: =AY33/100*$AZ$34 -> 0
A34: 1 | B34: 298 | C34: Quantity, m3 (STP/h) | D34: 1367.4569 | E34: =($A$34)*($D$34*1000)/($E$24*$B$34) -> 55193.428 | J34: Quantity, m3 (STP/h) | K34: =L34*$E$24*$B$34/$A$34/1000 -> 3131.4764 | L34: =E34+AI65 -> 126392.95 | R34: Quantity, m3 (STP/h) | S34: =T34*$E$24*$B$34/$A$34/1000 -> 6776.2629 | T34: =SUM(T27:T33) -> 273504.18 | U34: {=SUMPRODUCT(S27:S33/100,_xlfn.ANCHORARRAY(U27))} -> 26.852632 | Z34: 1.405855 | AA34: Quantity, m3 (STP/h) | AB34: =AC34*$E$24*$B$34/$A$34/1000 -> 9526.4431 | AC34: =T34*Z34 -> 384507.21 | AD34: {=SUMPRODUCT(AB27:AB33/100,_xlfn.ANCHORARRAY(AD27))} -> -20.275682 | AF34: SUM | AK34: SUM | AL34: =SUM(AL27:AL33) -> -3759263.2 | AO34: Quantity, m3 (STP/h) | AP34: =AQ34*$E$24*$B$34/$A$34/1000 -> 8455.4782 | AQ34: =SUM(AQ27:AQ33) -> 341280.83 | AT34: Quantity, m3 (STP/h) | AU34: =AV34*$E$24*$B$34/$A$34/1000 -> 7203.2443 | AV34: =SUM(AV27:AV33) -> 290738.04 | AX34: Quantity, m3 (STP/h) | AY34: 5000.5 | AZ34: =($A$34)*($AY$34*1000)/($E$24*$B$34) -> 201830.66
C35: Temperature, °C | D35: 20 | J35: Temperature, °C | K35: 390 | R35: Temperature, °C | S35: 520 | X35: =T31*X36*Z31 -> 12185067 | AA35: Temperature, °C | AB35: 1100 | AF35: {=SUMPRODUCT(AB27:AB33/100,_xlfn.ANCHORARRAY(AF27))} -> -6.7129394 | AO35: Temperature, °C | AP35: 20 | AT35: Temperature, °C | AU35: 20 | AX35: Temperature, °C | AY35: 20
C36: Pressure, MPa | D36: 5.4 | J36: Pressure, MPa | K36: 5.3 | R36: Pressure, MPa | S36: 5.3 | U36: =U34*T34 -> 7344307 | X36: 233.78 | AA36: Pressure, MPa | AB36: 5.1 | AF36: =AF35*AC34 -> -2581173.6 | AO36: Pressure, MPa | AP36: 5 | AT36: Pressure, MPa | AU36: 5 | AX36: Pressure, MPa | AY36: 4.9
H37: =SUM(H27:H33) -> 1586380.2 | J37: SUM | P37: =SUM(P27:P33) -> 1421407.4 | R37: SUM | V37: =SUM(V27:V33) -> 7344307 | X37: =SUM(X27:X28,X30) -> 12588868 | Y37: =SUM(P37,V37,X37)/(1-(Y32))*Y32 -> 0 | AE37: =SUM(AE27:AE33) -> -7796145.8 | AG37: =SUM(AG27:AG33) -> -2581173.6
H38: 1311383.6
D39: =AV23-BA27 -> -3.8743044e-05 | K39: If too high CO CO2 contents for desulphurization, recycle adding after desulphurization | U39: Overall
D40: =(E31-AY63)*4+E32*7-AY61-(AZ27+AT6+AY59) -> 1409.6937 | U40: heat-adding | V40: heat-consuming
AG41: Temperature increase check | AT41: Purge gas recycle | AU41: Mole, mol | AW41: Parameter | AX41: Purge gas recycle | AY41: Mole, mol
...

Sheet OCMC eSMR NASA
F1: Parameter | G1: Feed, 1 | H1: Before desulfurization, 2 | I1: Reformer inlet, 3 | J1: Reformer outlet, 4 | K1: Pressure swing adsorption, 5 | L1: H2 product, 6
F2: H2, vol % | G2: 0 | H2: 4.8 | I2: 1.1 | J2: 51.9 | K2: 74.6 | L2: 99.99
F3: N2, vol % | G3: 1 | H3: 1 | I3: 0.3 | J3: 0.2 | K3: 0.25 | L3: 0.01
F4: CO, vol % | G4: 0 | H4: 0 | I4: 0 | J4: 10.7 | K4: 5.3 | L4: 0 | AN4: id Gas
F5: CO2, vol % | G5: 0.5 | H5: 0.5 | I5: 0.1 | J5: 5.1 | K5: 14.8 | L5: 0 | AN5: Henry-coefficient | AO5: S_(i/CO2)=H_CO2/H_i | AP5: p_i/p_CO2 | AQ5: n_i=n_CO2*(p_i/p_CO2)*S_(i/CO2) | AR5: Parameter | AS5: CO2 for CCU | AT5: Mole, mol | AU5: Mass flow, kg/h
F6: CH4, vol % | G6: 95 | H6: 90.4 | I6: 26.1 | J6: 3.8 | K6: 4.9 | L6: 0 | AN6: 626 | AO6: =$AN$9/AN6 -> 0.0079872204 | AP6: =AQ27/$AQ$30 -> 4.7907332 | AQ6: =$AT$9*AO6*AP6 -> 1811.6996 | AR6: H2, vol % | AS6: =AT6/$AT$13*100 -> 3.5844871 | AT6: =AQ6 -> 1811.6996
F7: C2+, vol % | G7: 3.5 | H7: 3.3 | I7: 1 | J7: 0 | K7: 0 | L7: 0 | AN7: 364 | AO7: =$AN$9/AN7 -> 0.013736264 | AP7: =AQ28/$AQ$30 -> 0.050140283 | AQ7: =$AT$9*AO7*AP7 -> 32.609485 | AR7: N2, vol % | AS7: =AT7/$AT$13*100 -> 0.064518576 | AT7: =AQ7 -> 32.609485
F8: H2O, vol % | G8: 0 | H8: 0 | I8: 71.4 | J8: 28.3 | K8: 0.15 | L8: 0 | AN8: 239 | AO8: =$AN$9/AN8 -> 0.020920502 | AP8: =AQ29/$AQ$30 -> 0.67961032 | AQ8: =$AT$9*AO8*AP8 -> 673.16357 | AR8: CO, vol % | AS8: =AT8/$AT$13*100 -> 1.3318688 | AT8: =AQ8 -> 673.16357
F9: Quantity, m3 (STP/h) | G9: 2160 | H9: 2070 | I9: 7160 | J9: 10450 | K9: 8180 | L9: 5000.5 | AN9: 5 | AO9: =$AN$9/AN9 -> 1 | AP9: =AQ30/$AQ$30 -> 1 | AQ9: =$AT$9*AO9*AP9 -> 47346.571 | AR9: CO2, vol % | AS9: =AT9/$AT$13*100 -> 93.676223 | AT9: =AQ30-AV30 -> 47346.571 | AU9: =AT9*44/1000 -> 2083.2491
F10: Temperature, °C | G10: 20 | H10: 390 | I10: 520 | J10: 850 | K10: 20 | L10: 20 | AN10: 91.8 | AO10: =$AN$9/AN10 -> 0.054466231 | AP10: =AQ31/$AQ$30 -> 0.06468899 | AQ10: =$AT$9*AO10*AP10 -> 166.81927 | AR10: CH4, vol % | AS10: =AT10/$AT$13*100 -> 0.33005557 | AT10: =AQ10 -> 166.81927
F11: Pressure, MPa | G11: 2 | H11: 1.9 | I11: 1.9 | J11: 1.7 | K11: 1.6 | L11: 1.5 | AN11: 10.25 | AO11: =$AN$9/AN11 -> 0.48780488 | AP11: =AQ32/$AQ$30 -> 0 | AQ11: =$AT$9*AO11*AP11 -> 0 | AR11: C2+, vol % | AS11: =AT11/$AT$13*100 -> 0 | AT11: =AQ11 -> 0
P12: isenthalpic | AR12: H2O, vol % | AS12: =AT12/$AT$13*100 -> 1.0128473 | AT12: =AQ33 -> 511.92124
N13: Parameter | O13: HP reforming steam import | P13: From water to steam | Q13: Mole, mol | R13: Mass flow, kg/h | S13: Energy, kJ/h | AR13: Quantity, m3 (STP/h) | AS13: =AT13*$E$24*$B$34/$A$34/1000 -> 1252.2339 | AT13: =SUM(AT6:AT12) -> 50542.785
N14: Energy, kJ/kg | O14: 3166.1 | P14: =3166.1-84 -> 3082.1 | T14: https://www.peacesoftware.de/einigewerte/wasser_dampf.html | AR14: Temperature, °C | AS14: 20
N15: H2O, vol % | O15: 100 | Q15: =T33-L33 -> 147111.23 | R15: =Q15*18/1000 -> 2648.0021 | S15: =P14*R15 -> 8161407.1 | AR15: Pressure, MPa | AS15: 0.1
N16: Quantity, m3 (STP/h) | O16: =Q15*$E$24*$B$34/$A$34/1000 -> 3644.7865
N17: Temperature, °C | O17: 390 | P17: 390 | AM17: Parameter | AN17: Waste water | AO17: Mole, mol | AP17: Mass flow, kg/h
N18: Pressure, MPa | O18: 5.3 | P18: 5.3 | AM18: Specific enthalpy, kJ/kg | AN18: 84
AM19: H2O, vol % | AN19: 100 | AO19: =AC33-AQ33 -> 81109.348 | AP19: =AO19*18/1000 -> 1459.9683 | AQ19: =AN18*AP19 -> 122637.33
M20: S/C | AM20: Temperature, °C | AN20: 20 | AO20: https://www.peacesoftware.de/einigewerte/wasser_dampf.html
M21: 2.5 | AM21: Pressure, MPa | AN21: 0.1
AH22: T_in | AI22: T_out
E23: R | AD23: T_out HXI | AH23: 313.89263 | AI23: 440 | AR23: 1 – 2 % can even be reached in the main wash part with just ﬂash-regenerated methanol. Therefore external energy input is neglected as first simplification | AV23: 0.82 | AW23: H2 recovery
E24: 0.08314 | AD24: =S35 -> 520
C26: Parameter | D26: Feed, 1 | E26: Mole, mol | G26: Molar heat capacity, kJ/mol | H26: Heat-up energy, kJ/h | J26: Parameter | K26: Before desulfurization, 2 | L26: Mole, mol | O26: Molar heat capacity, kJ/mol | P26: Heat-up energy, kJ/h | R26: Parameter | S26: Reformer inlet, 3 | T26: Mole, mol | U26: Molar heat capacity, kJ/mol | V26: Heat-up energy, kJ/h | W26: Reaction number | X26: Reaction enthalpy, kJ/h | Y26: Insulation losses, kJ | AA26: Parameter | AB26: Reformer outlet, 4 | AC26: Mole, mol | AD26: Molar heat capacity, kJ/mol | AE26: Heat-down energy, kJ/h | AF26: Molar heat capacity, kJ/mol | AG26: Heat-down energy, kJ/h | AK26: Molar heat capacity, kJ/mol | AL26: Heat-down energy, kJ/h | AO26: Parameter | AP26: Pressure swing adsorption, 5 | AQ26: Mole, mol | AT26: Parameter | AU26: Pressure swing adsorption, 5 | AV26: Mole, mol | AX26: Parameter | AY26: H2 product, 6 | AZ26: Mole, mol
C27: H2, vol % | D27: 0 | E27: =($A$34)*($D$34*D27/100*1000)/($E$24*$B$34) -> 0 | G27: {=N91:N97} -> 11.412697 | H27: =G27*L27 -> 404777.26 | J27: H2, vol % | K27: =L27/$L$34*100 -> 28.061119 | L27: =E27+AI58 -> 35467.276 | O27: {=N99:N105} -> 3.9119754 | P27: =T27*O27 -> 138747.11 | R27: H2, vol % | S27: =T27/$T$34*100 -> 12.967727 | T27: =L27 -> 35467.276 | U27: {=N107:N113} -> 17.899022 | V27: =T27*U27 -> 634829.56 | W27: I | X27: =Z108*AI121 -> 11665860 | Y27: min | AA27: H2, vol % | AB27: 54.6059 | AC27: =AB27/100*$AC$34 -> 209963.62 | AD27: {=N115:N121} -> -17.899022 | AE27: =AC27*AD27 -> -3758143.6 | AF27: {=N123:N129} -> -6.2076423 | AG27: =AC27*AF27 -> -1303379.1 | AK27: {=N131:N137} -> -12.917366 | AL27: =AK27*AV27 -> -3178947.2 | AO27: H2, vol % | AP27: =AQ27/$AQ$34*100 -> 72.641178 | AQ27: =AC27+AC29*AH29 -> 247910.41 | AT27: H2, vol % | AU27: =AV27/$AV$34*100 -> 84.646203 | AV27: =AQ27-AT6 -> 246098.71 | AX27: H2, vol % | AY27: 99.99 | AZ27: =AY27/100*$AZ$34 -> 201810.48 | BA27: =AZ27/AV27 -> 0.82003874
C28: N2, vol % | D28: 1 | E28: =($A$34)*($D$34*D28/100*1000)/($E$24*$B$34) -> 551.93428 | G28: 9.0299095 | H28: =G28*L28 -> 23365.142 | J28: N2, vol % | K28: =L28/$L$34*100 -> 2.047209 | L28: =E28+AI59 -> 2587.5278 | O28: 3.7626703 | P28: =T28*O28 -> 9736.0143 | R28: N2, vol % | S28: =T28/$T$34*100 -> 0.9460652 | T28: =L28 -> 2587.5278 | U28: 18.616532 | V28: =T28*U28 -> 48170.796 | W28: IV | X28: =Z107*AI126 -> -313301.18 | Y28: 0.01 | AA28: N2, vol % | AB28: 0.6748 | AC28: =AB28/100*$AC$34 -> 2594.6547 | AD28: -18.616532 | AE28: =AC28*AD28 -> -48303.473 | AF28: -5.8595386 | AG28: =AC28*AF28 -> -15203.479 | AK28: -10.452252 | AL28: =AK28*AV28 -> -26779.141 | AO28: N2, vol % | AP28: =AQ28/$AQ$34*100 -> 0.76026969 | AQ28: =AC28 -> 2594.6547 | AT28: N2, vol % | AU28: =AV28/$AV$34*100 -> 0.88122118 | AV28: =AQ28-AT7 -> 2562.0452 | AX28: N2, vol % | AY28: 0.01 | AZ28: =AY28/100*$AZ$34 -> 20.183066
C29: CO, vol % | D29: 0 | E29: =($A$34)*($D$34*D29/100*1000)/($E$24*$B$34) -> 0 | G29: 10.524394 | H29: =G29*L29 -> 290733.74 | J29: CO, vol % | K29: =L29/$L$34*100 -> 21.856242 | L29: =E29+AI60 -> 27624.749 | O29: 4.0133733 | P29: =T29*O29 -> 110868.43 | R29: CO, vol % | S29: =T29/$T$34*100 -> 10.100303 | T29: =L29 -> 27624.749 | U29: 19.303674 | V29: =T29*U29 -> 533259.15 | W29: VII | X29: not relevant | Y29: max | AA29: CO, vol % | AB29: 19.0153 | AC29: =AB29/100*$AC$34 -> 73115.2 | AD29: -19.303674 | AE29: =AC29*AD29 -> -1411392 | AF29: -6.2944433 | AG29: =AC29*AF29 -> -460219.48 | AH29: 0.519 | AI29: CO-conversion | AK29: -12.051072 | AL29: =AK29*AV29 -> -415704.72 | AO29: CO, vol % | AP29: =AQ29/$AQ$34*100 -> 10.304831 | AQ29: =AC29*(1-AH29) -> 35168.411 | AT29: CO, vol % | AU29: =AV29/$AV$34*100 -> 11.864718 | AV29: =AQ29-AT8 -> 34495.248 | AX29: CO, vol % | AY29: 0 | AZ29: =AY29/100*$AZ$34 -> 0
C30: CO2, vol % | D30: 0.5 | E30: =($A$34)*($D$34*D30/100*1000)/($E$24*$B$34) -> 275.96714 | G30: 16.648488 | H30: =G30*L30 -> 63275.544 | J30: CO2, vol % | K30: =L30/$L$34*100 -> 3.0070332 | L30: =E30+AI61 -> 3800.6781 | O30: 6.580752 | P30: =T30*O30 -> 25011.32 | R30: CO2, vol % | S30: =T30/$T$34*100 -> 1.3896234 | T30: =L30 -> 3800.6781 | U30: 32.044939 | V30: =T30*U30 -> 121792.5 | W30: VIII | X30: =Z109*AI135 -> 730269.61 | Y30: 0.05 | Z30: CH4 Umsatz | AA30: CO2, vol % | AB30: 3.5893 | AC30: =AB30/100*$AC$34 -> 13801.117 | AD30: -32.044939 | AE30: =AC30*AD30 -> -442255.97 | AF30: -10.280325 | AG30: =AC30*AF30 -> -141879.97 | AK30: -19.143103 | AL30: =AK30*AV30 -> -84255.209 | AO30: CO2, vol % | AP30: =AQ30/$AQ$34*100 -> 15.162852 | AQ30: =AC30+(AC29*AH29) -> 51747.906 | AS30: [Ullmann's, Gas Production, 3. Gas Treating, 504] | AT30: CO2, vol % | AU30: 1.5 | AV30: =SUM(AQ27:AQ29,AQ31:AQ32)/(1-(AU30/100))*(AU30/100) -> 4401.335 | AX30: CO2, vol % | AY30: 0 | AZ30: =AY30/100*$AZ$34 -> 0
B31: 74 | C31: CH4, vol % | D31: 95 | E31: =($A$34)*($D$34*D31/100*1000)/($E$24*$B$34) -> 52433.757 | G31: 14.130909 | H31: =G31*L31 -> 776930.81 | J31: CH4, vol % | K31: =L31/$L$34*100 -> 43.500013 | L31: =E31+AI62 -> 54980.95 | O31: 7.3660903 | P31: =T31*O31 -> 404994.64 | R31: CH4, vol % | S31: =T31/$T$34*100 -> 20.102417 | T31: =L31 -> 54980.95 | U31: 42.380994 | V31: =T31*U31 -> 2330147.3 | Y31: 1100°C | Z31: 0.948 | AA31: CH4, vol % | AB31: 0.8706 | AC31: =AB31/100*$AC$34 -> 3347.5198 | AD31: -42.380994 | AE31: =AC31*AD31 -> -141871.22 | AF31: -11.183194 | AG31: =AC31*AF31 -> -37435.963 | AK31: -16.844385 | AL31: =AK31*AV31 -> -53576.944 | AO31: CH4, vol % | AP31: =AQ31/$AQ$34*100 -> 0.98086958 | AQ31: =AC31 -> 3347.5198 | AT31: CH4, vol % | AU31: =AV31/$AV$34*100 -> 1.0940091 | AV31: =AQ31-AT10 -> 3180.7005 | AX31: CH4, vol % | AY31: 0 | AZ31: =AY31/100*$AZ$34 -> 0
C32: C2+, vol % | D32: 3.5 | E32: =($A$34)*($D$34*D32/100*1000)/($E$24*$B$34) -> 1931.77 | G32: 14.130909 | H32: =G32*L32 -> 27297.666 | J32: C2+, vol % | K32: =L32/$L$34*100 -> 1.5283843 | L32: =E32+AI63 -> 1931.77 | O32: 7.3660903 | P32: =T32*O32 -> 14229.592 | R32: C2+, vol % | S32: =T32/$T$34*100 -> 0.70630366 | T32: =L32 -> 1931.77 | U32: 42.380994 | V32: =T32*U32 -> 81870.333 | Y32: 0 | AA32: C2+, vol % | AB32: 0 | AC32: =AB32/100*$AC$34 -> 0 | AD32: -42.380994 | AE32: =AC32*AD32 -> 0 | AF32: -11.183194 | AG32: =AC32*AF32 -> 0 | AK32: -16.844385 | AL32: =AK32*AV32 -> 0 | AO32: C2+, vol % | AP32: =AQ32/$AQ$34*100 -> 0 | AQ32: =AC32 -> 0 | AT32: C2+, vol % | AU32: =AV32/$AV$34*100 -> 0 | AV32: =AQ32-AT11 -> 0 | AX32: C2+, vol % | AY32: 0 | AZ32: =AY32/100*$AZ$34 -> 0
A33: p_0 | B33: T_0 | C33: H2O, vol % | D33: 0 | E33: =($A$34)*($D$34*D33/100*1000)/($E$24*$B$34) -> 0 | G33: 12.671218 | H33: =G33*L33 -> 0 | J33: H2O, vol % | K33: =L33/$L$34*100 -> 0 | L33: =E33+AI64 -> 0 | O33: 4.8794395 | P33: =T33*O33 -> 717820.33 | R33: H2O, vol % | S33: =T33/$T$34*100 -> 53.787561 | T33: =(T31+2*T32)*M21 -> 147111.23 | U33: 24.432108 | V33: =T33*U33 -> 3594237.3 | Z33: mol_out/mol_in | AA33: H2O, vol % | AB33: 21.2275 | AC33: =AB33/100*$AC$34 -> 81621.269 | AD33: -24.432108 | AE33: =AC33*AD33 -> -1994179.6 | AF33: -7.6334962 | AG33: =AC33*AF33 -> -623055.65 | AK33: -14.521697 | AL33: =AK33*AV33 -> 0 | AO33: H2O, vol % | AP33: 0.15 | AQ33: =SUM(AQ27:AQ32)/(1-(AP33/100))*(AP33/100) -> 511.92124 | AT33: H2O, vol % | AU33: =AV33/$AV$34*100 -> 0 | AV33: =AQ33-AT12 -> 0 | AX33: H2O, vol % | AY33: 0 | AZ33: =AY33/100*$AZ$34 -> 0
A34: 1 | B34: 298 | C34: Quantity, m3 (STP/h) | D34: 1367.4569 | E34: =($A$34)*($D$34*1000)/($E$24*$B$34) -> 55193.428 | J34: Quantity, m3 (STP/h) | K34: =L34*$E$24*$B$34/$A$34/1000 -> 3131.4764 | L34: =E34+AI65 -> 126392.95 | R34: Quantity, m3 (STP/h) | S34: =T34*$E$24*$B$34/$A$34/1000 -> 6776.2629 | T34: =SUM(T27:T33) -> 273504.18 | U34: {=SUMPRODUCT(S27:S33/100,_xlfn.ANCHORARRAY(U27))} -> 26.852632 | Z34: 1.405855 | AA34: Quantity, m3 (STP/h) | AB34: =AC34*$E$24*$B$34/$A$34/1000 -> 9526.4431 | AC34: =T34*Z34 -> 384507.21 | AD34: {=SUMPRODUCT(AB27:AB33/100,_xlfn.ANCHORARRAY(AD27))} -> -20.275682 | AF34: SUM | AK34: SUM | AL34: =SUM(AL27:AL33) -> -3759263.2 | AO34: Quantity, m3 (STP/h) | AP34: =AQ34*$E$24*$B$34/$A$34/1000 -> 8455.4782 | AQ34: =SUM(AQ27:AQ33) -> 341280.83 | AT34: Quantity, m3 (STP/h) | AU34: =AV34*$E$24*$B$34/$A$34/1000 -> 7203.2443 | AV34: =SUM(AV27:AV33) -> 290738.04 | AX34: Quantity, m3 (STP/h) | AY34: 5000.5 | AZ34: =($A$34)*($AY$34*1000)/($E$24*$B$34) -> 201830.66
C35: Temperature, °C | D35: 20 | J35: Temperature, °C | K35: 390 | R35: Temperature, °C | S35: 520 | X35: =T31*X36 -> 15394666 | AA35: Temperature, °C | AB35: 1100 | AF35: {=SUMPRODUCT(AB27:AB33/100,_xlfn.ANCHORARRAY(AF27))} -> -6.7129394 | AO35: Temperature, °C | AP35: 20 | AT35: Temperature, °C | AU35: 20 | AX35: Temperature, °C | AY35: 20
C36: Pressure, MPa | D36: 5.4 | J36: Pressure, MPa | K36: 5.3 | R36: Pressure, MPa | S36: 5.3 | U36: =U34*T34 -> 7344307 | X36: 280 | AA36: Pressure, MPa | AB36: 5.1 | AF36: =AF35*AC34 -> -2581173.6 | AO36: Pressure, MPa | AP36: 5 | AT36: Pressure, MPa | AU36: 5 | AX36: Pressure, MPa | AY36: 4.9
H37: =SUM(H27:H33) -> 1586380.2 | J37: SUM | P37: =SUM(P27:P33) -> 1421407.4 | R37: SUM | V37: =SUM(V27:V33) -> 7344307 | X37: =SUM(X27:X28,X30) -> 12082829 | Y37: =SUM(P37,V37,X37)/(1-(Y32))*Y32 -> 0 | AE37: =SUM(AE27:AE33) -> -7796145.8 | AG37: =SUM(AG27:AG33) -> -2581173.6
E38: =E30+E31+2*E32 -> 56573.264 | H38: 1311383.6
D39: =AV23-BA27 -> -3.8743044e-05 | E39: =SUM(AY61:AY63)/E38 -> 0.14813779 | K39: If too high CO CO2 contents for desulphurization, recycle adding after desulphurization | U39: Overall
D40: =(E31-AY63)*4+E32*7-AY61-(AZ27+AT6+AY59) -> 1409.6937 | U40: heat-adding | V40: heat-consuming
AG41: Temperature increase check | AT41: Purge gas recycle | AU41: Mole, mol | AW41: Parameter | AX41: Purge gas recycle | AY41: Mole, mol
...

Sheet Sheet1
S1: R
S2: 8.314
A3: Spezies | B3: Temperaturgrenzen | E3: Low-T Koeffizienten (T_min → T_mid) | L3: High-T Koeffizienten (T_mid → T_max)
B4: T_min [K] | C4: T_mid [K] | D4: T_max [K] | E4: a1l | F4: a2l | G4: a3l | H4: a4l | I4: a5l | J4: a6l | K4: a7l | L4: a1h | M4: a2h | N4: a3h | O4: a4h | P4: a5h | Q4: a6h | R4: a7h
A5: H2 | B5: 200 | C5: 1000 | D5: 3500 | E5: 2.3443311 | F5: 0.0079805207 | G5: -1.9478151e-05 | H5: 2.0157209e-08 | I5: -7.3761176e-12 | J5: -917.93517 | K5: 0.68301024 | L5: 3.3372792 | M5: -4.9402473e-05 | N5: 4.9945678e-07 | O5: -1.7956639e-10 | P5: 2.0025538e-14 | Q5: -950.15892 | R5: -3.2050233
A6: N2 | B6: 300 | C6: 1000 | D6: 5000 | E6: 3.298677 | F6: 0.0014082404 | G6: -3.963222e-06 | H6: 5.641515e-09 | I6: -2.444854e-12 | J6: -1020.8999 | K6: 3.950372 | L6: 2.92664 | M6: 0.0014879768 | N6: -5.68476e-07 | O6: 1.0097038e-10 | P6: -6.753351e-15 | Q6: -922.7977 | R6: 5.980528
A7: CO | B7: 200 | C7: 1000 | D7: 3500 | E7: 3.5795335 | F7: -0.00061035368 | G7: 1.0168143e-06 | H7: 9.0700588e-10 | I7: -9.044245e-13 | J7: -14344.086 | K7: 3.5084093 | L7: 2.7151856 | M7: 0.0020625274 | N7: -9.9882577e-07 | O7: 2.3005301e-10 | P7: -2.0364772e-14 | Q7: -14151.872 | R7: 7.8186877
A8: CO2 | B8: 200 | C8: 1000 | D8: 3500 | E8: 2.3567735 | F8: 0.0089845968 | G8: -7.1235627e-06 | H8: 2.4591902e-09 | I8: -1.4369955e-13 | J8: -48371.97 | K8: 9.9010522 | L8: 3.8574603 | M8: 0.0044143703 | N8: -2.214814e-06 | O8: 5.2349019e-10 | P8: -4.7208416e-14 | Q8: -48759.166 | R8: 2.2716381
A9: CH4 | B9: 200 | C9: 1000 | D9: 3500 | E9: 5.1498761 | F9: -0.013670979 | G9: 4.918006e-05 | H9: -4.8474303e-08 | I9: 1.6669396e-11 | J9: -10246.648 | K9: -4.6413038 | L9: 0.074851495 | M9: 0.013390947 | N9: -5.7328581e-06 | O9: 1.2229254e-09 | P9: -1.0181523e-13 | Q9: -9468.3446 | R9: 18.437318
A10: C2H6 | B10: 200 | C10: 1000 | D10: 3500 | E10: 4.2914249 | F10: -0.0055015427 | G10: 5.9943829e-05 | H10: -7.0846629e-08 | I10: 2.6868577e-11 | J10: -11522.206 | K10: 2.6668232 | L10: 1.0718815 | M10: 0.021685268 | N10: -1.0025607e-05 | O10: 2.21412e-09 | P10: -1.9000289e-13 | Q10: -11426.393 | R10: 15.115611
A11: H2O | B11: 200 | C11: 1000 | D11: 3500 | E11: 4.1986406 | F11: -0.0020364341 | G11: 6.5204021e-06 | H11: -5.4879706e-09 | I11: 1.7719782e-12 | J11: -30293.727 | K11: -0.84903221 | L11: 3.0339925 | M11: 0.002176918 | N11: -1.6407252e-07 | O11: -9.7041987e-11 | P11: 1.6820099e-14 | Q11: -30004.297 | R11: 4.9667701

Sheet SMR, WGSR, C-forming, C2H6
F1: Parameter | G1: Feed, 1 | H1: Before desulfurization, 2 | I1: Reformer inlet, 3 | J1: Reformer outlet, 4 | K1: Pressure swing adsorption, 5 | L1: H2 product, 6 | U1: Parameter | V1: Steam export | Z1: Parameter | AA1: Flue gas (feed) | AB1: Mole, mol | AC1: Mass CO2, kg/h
F2: H2, vol % | G2: 0 | H2: 4.8 | I2: 1.1 | J2: 51.9 | K2: 74.6 | L2: 99.99 | U2: Specific enthalpy increase relative to input water, kJ/kg | V2: =2871.7 -> 2871.7 | W2: https://www.peacesoftware.de/einigewerte/wasser_dampf.html | Z2: H2, vol % | AA2: =AB2/SUM($AB$2:$AB$8)*100 -> 0 | AB2: 0
F3: N2, vol % | G3: 1 | H3: 1 | I3: 0.3 | J3: 0.2 | K3: 0.25 | L3: 0.01 | U3: Mass flow, kg/h | V3: =W15-S15 -> 985.86697 | Z3: N2, vol % | AA3: =AB3/SUM($AB$2:$AB$8)*100 -> 61.814141 | AB3: =N67+AC43+AB70 -> 289810.03
F4: CO, vol % | G4: 0 | H4: 0 | I4: 0 | J4: 10.7 | K4: 5.3 | L4: 0 | U4: Temperature, °C | V4: 255 | Z4: CO, vol % | AA4: =AB4/SUM($AB$2:$AB$8)*100 -> 0 | AB4: 0
F5: CO2, vol % | G5: 0.5 | H5: 0.5 | I5: 0.1 | J5: 5.1 | K5: 14.8 | L5: 0 | U5: Pressure, MPa | V5: 3 | Z5: CO2, vol % | AA5: =AB5/SUM($AB$2:$AB$8)*100 -> 19.276245 | AB5: =N69+N70+2*N71+AC44+AC45+AC46 -> 90374.939 | AC5: =AB5*44/1000 -> 3976.4973
F6: CH4, vol % | G6: 95 | H6: 90.4 | I6: 26.1 | J6: 3.8 | K6: 4.9 | L6: 0 | Z6: CH4, vol % | AA6: =AB6/SUM($AB$2:$AB$8)*100 -> 0 | AB6: 0
F7: C2+, vol % | G7: 3.5 | H7: 3.3 | I7: 1 | J7: 0 | K7: 0 | L7: 0 | Z7: C2+, vol % | AA7: =AB7/SUM($AB$2:$AB$8)*100 -> 0 | AB7: 0
F8: H2O, vol % | G8: 0 | H8: 0 | I8: 71.4 | J8: 28.3 | K8: 0.15 | L8: 0 | Z8: H2O, vol % | AA8: =AB8/SUM($AB$2:$AB$8)*100 -> 18.909614 | AB8: =N70*2+N71*3+AC42+AC46*2+AC48 -> 88656.022
F9: Quantity, m3 (STP/h) | G9: 2160 | H9: 2070 | I9: 7160 | J9: 10450 | K9: 8180 | L9: 5000.5 | Z9: Quantity, m3 (STP/h) | AA9: =SUM(AB2:AB8)*W11*Y11/X11/1000 -> 11615.873
F10: Temperature, °C | G10: 20 | H10: 390 | I10: 520 | J10: 850 | K10: 20 | L10: 20 | Z10: Temperature, °C | AA10: not stated
F11: Pressure, MPa | G11: 2 | H11: 1.9 | I11: 1.9 | J11: 1.7 | K11: 1.6 | L11: 1.5 | W11: 0.08314 | X11: 1 | Y11: 298 | Z11: Pressure, MPa
Q12: isenthalpic | AA12: min | AB12: max | AC12: average | AD12: Lost energy, kJ/h
O13: Parameter | P13: MP reforming steam | R13: Mole, mol | S13: Mass flow, kg/h | V13: Parameter | W13: Steam byproduct | X13: Energy, kJ/h | Z13: Flue gas losses | AA13: 0.06 | AB13: 0.1 | AC13: =AVERAGE(AA13:AB13) -> 0.08 | AD13: =-AC13*SUM(P76,AG52) -> 2561471
O14: Specific enthalpy, kJ/kg | P14: =2871.7 -> 2871.7 | Q14: 2871.5 | V14: Specific enthalpy increase relative to input water, kJ/kg | W14: =2871.7 -> 2871.7 | X14: https://www.peacesoftware.de/einigewerte/wasser_dampf.html
O15: H2O, vol % | P15: 100 | R15: =($A$34)*($P$16*P15/100*1000)/($E$24*$B$34) -> 206340.72 | S15: =R15*18/1000 -> 3714.133 | V15: Mass flow, kg/h | W15: 4700 | X15: =W14*W15 -> 13496990 | AA15: [Ullmanns, Hydrogen, 2. Production, 266] | AB15: [Ullmanns, Hydrogen, 2. Production, 266] | AI15: Parameter | AJ15: Water | AK15: Energy, kJ/h | AM15: Parameter | AN15: Waste water | AO15: Mole, mol | AP15: Mass flow, kg/h
O16: Quantity, m3 (STP/h) | P16: =S33/100*S34 -> 5112.24 | AI16: Specific enthalpy increase relative to input water, kJ/kg | AJ16: =84 -> 84 | AK16: https://www.peacesoftware.de/einigewerte/wasser_dampf.html | AM16: Specific enthalpy, kJ/kg | AN16: 84
O17: Temperature, °C | P17: =W17 -> 255 | Q17: 236 | R17: https://www.peacesoftware.de/einigewerte/wasser_dampf.html | V17: Temperature, °C | W17: 255 | AI17: Mass flow, kg/h | AJ17: 4700 | AK17: =AJ16*AJ17 -> 394800 | AM17: H2O, vol % | AN17: 100 | AO17: =AC33-AP33 -> 118869.6 | AP17: =AO17*18/1000 -> 2139.6529
O18: Pressure, MPa | P18: 3 | Q18: 1.9 | V18: Pressure, MPa | W18: 3 | AI18: Temperature, °C | AJ18: 255 | AM18: Temperature, °C | AN18: 20 | AO18: https://www.peacesoftware.de/einigewerte/wasser_dampf.html
AI19: Pressure, MPa | AJ19: 3 | AM19: Pressure, MPa | AN19: 0.1
AH22: T_in | AI22: T_out
E23: R | AH23: 350 | AI23: 437.86394
E24: 0.08314
C26: Parameter | D26: Feed, 1 | E26: Mole, mol | G26: Molar heat capacity, kJ/mol | H26: Heat-up energy, kJ/h | J26: Parameter | K26: Before desulfurization, 2 | L26: Mole, mol | O26: Molar heat capacity, kJ/mol | P26: Heat-up energy, kJ/h | R26: Parameter | S26: Reformer inlet, 3 | T26: Mole, mol | U26: Molar heat capacity, kJ/mol | V26: Heat-up energy, kJ/h | W26: Reaction number | X26: Reaction enthalpy, kJ/h | Y26: Insulation losses, kJ | AA26: Parameter | AB26: Reformer outlet, 4 | AC26: Mole, mol | AE26: Molar heat capacity, kJ/mol | AF26: Heat-down energy, kJ/h | AK26: Molar heat capacity, kJ/mol | AL26: Heat-down energy, kJ/h | AN26: Parameter | AO26: Pressure swing adsorption, 5 | AP26: Mole, mol | AR26: Parameter | AS26: H2 product, 6 | AT26: Mole, mol
C27: H2, vol % | D27: 0 | E27: =($A$34)*($D$34*D27/100*1000)/($E$24*$B$34) -> 0 | G27: {=N91:N97} -> 11.412697 | H27: =G27*L27 -> 45769.226 | J27: H2, vol % | K27: 4.8 | L27: =($A$34)*($K$34*K27/100*1000)/($E$24*$B$34) -> 4010.3779 | O27: {=N99:N105} -> 3.9119754 | P27: =T27*O27 -> 12435.852 | R27: H2, vol % | S27: 1.1 | T27: =($A$34)*($S$34*S27/100*1000)/($E$24*$B$34) -> 3178.9187 | U27: {=N107:N113} -> 10.046576 | V27: =T27*U27 -> 31937.249 | W27: I | X27: =Z108*AC121 -> 13778604 | Y27: min | AA27: H2, vol % | AB27: 51.9 | AC27: =($A$34)*($AB$34*AB27/100*1000)/($E$24*$B$34) -> 218905.85 | AE27: {=N115:N121} -> -15.163908 | AF27: =AC27*AE27 -> -3319468.1 | AK27: {=N123:N129} -> -12.853107 | AL27: =AK27*AP27 -> -3165730.7 | AN27: H2, vol % | AO27: 74.6 | AP27: =($A$34)*($AO$34*AO27/100*1000)/($E$24*$B$34) -> 246300.81 | AR27: H2, vol % | AS27: 99.99 | AT27: =AS27/100*$AT$34 -> 201810.48
C28: N2, vol % | D28: 1 | E28: =($A$34)*($D$34*D28/100*1000)/($E$24*$B$34) -> 871.82128 | G28: 9.0299095 | H28: =G28*L28 -> 7544.4479 | J28: N2, vol % | K28: 1 | L28: =($A$34)*($K$34*K28/100*1000)/($E$24*$B$34) -> 835.4954 | O28: 3.7626703 | P28: =T28*O28 -> 3262.1518 | R28: N2, vol % | S28: 0.3 | T28: =($A$34)*($S$34*S28/100*1000)/($E$24*$B$34) -> 866.97783 | U28: 10.307807 | V28: =T28*U28 -> 8936.6404 | W28: IV | X28: =Z107*AC126 -> -659661.69 | Y28: 0.01 | AA28: N2, vol % | AB28: 0.2 | AC28: =($A$34)*($AB$34*AB28/100*1000)/($E$24*$B$34) -> 843.56782 | AE28: -15.183445 | AF28: =AC28*AE28 -> -12808.265 | AK28: -10.39082 | AL28: =AK28*AP28 -> -8576.6335 | AN28: N2, vol % | AO28: 0.25 | AP28: =($A$34)*($AO$34*AO28/100*1000)/($E$24*$B$34) -> 825.40487 | AR28: N2, vol % | AS28: 0.01 | AT28: =AS28/100*$AT$34 -> 20.183066
C29: CO, vol % | D29: 0 | E29: =($A$34)*($D$34*D29/100*1000)/($E$24*$B$34) -> 0 | G29: 0 | H29: =G29*L29 -> 0 | J29: CO, vol % | K29: 0 | L29: =($A$34)*($K$34*K29/100*1000)/($E$24*$B$34) -> 0 | O29: 0 | P29: =T29*O29 -> 0 | R29: CO, vol % | S29: 0 | T29: =($A$34)*($S$34*S29/100*1000)/($E$24*$B$34) -> 0 | U29: 0 | V29: =T29*U29 -> 0 | W29: VII | X29: not relevant | Y29: max | AA29: CO, vol % | AB29: 10.7 | AC29: =($A$34)*($AB$34*AB29/100*1000)/($E$24*$B$34) -> 45130.878 | AE29: -15.976905 | AF29: =AC29*AE29 -> -721051.75 | AK29: -11.985409 | AL29: =AK29*AP29 -> -209727.68 | AN29: CO, vol % | AO29: 5.3 | AP29: =($A$34)*($AO$34*AO29/100*1000)/($E$24*$B$34) -> 17498.583 | AR29: CO, vol % | AS29: 0 | AT29: =AS29/100*$AT$34 -> 0
C30: CO2, vol % | D30: 0.5 | E30: =($A$34)*($D$34*D30/100*1000)/($E$24*$B$34) -> 435.91064 | G30: 16.648488 | H30: =G30*L30 -> 6954.8676 | J30: CO2, vol % | K30: 0.5 | L30: =($A$34)*($K$34*K30/100*1000)/($E$24*$B$34) -> 417.7477 | O30: 6.580752 | P30: =T30*O30 -> 1901.7887 | R30: CO2, vol % | S30: 0.1 | T30: =($A$34)*($S$34*S30/100*1000)/($E$24*$B$34) -> 288.99261 | U30: 17.816398 | V30: =T30*U30 -> 5148.8074 | W30: VIII | X30: =Z109*AC135 -> 1206475.2 | Y30: 0.05 | AA30: CO2, vol % | AB30: 5.1 | AC30: =($A$34)*($AB$34*AB30/100*1000)/($E$24*$B$34) -> 21510.979 | AE30: -26.356923 | AF30: =AC30*AE30 -> -566963.22 | AK30: -19.035557 | AL30: =AK30*AP30 -> -930152.83 | AN30: CO2, vol % | AO30: 14.8 | AP30: =($A$34)*($AO$34*AO30/100*1000)/($E$24*$B$34) -> 48863.968 | AR30: CO2, vol % | AS30: 0 | AT30: =AS30/100*$AT$34 -> 0
C31: CH4, vol % | D31: 95 | E31: =($A$34)*($D$34*D31/100*1000)/($E$24*$B$34) -> 82823.022 | G31: 14.130909 | H31: =G31*L31 -> 1067290.4 | J31: CH4, vol % | K31: 90.4 | L31: =($A$34)*($K$34*K31/100*1000)/($E$24*$B$34) -> 75528.784 | O31: 7.3660903 | P31: =T31*O31 -> 555602.62 | R31: CH4, vol % | S31: 26.1 | T31: =($A$34)*($S$34*S31/100*1000)/($E$24*$B$34) -> 75427.071 | U31: 22.55655 | V31: =T31*U31 -> 1701374.5 | Y31: average | AA31: CH4, vol % | AB31: 3.8 | AC31: =($A$34)*($AB$34*AB31/100*1000)/($E$24*$B$34) -> 16027.788 | AE31: -31.977801 | AF31: =AC31*AE31 -> -512533.42 | AK31: -16.725299 | AL31: =AK31*AP31 -> -270580.81 | AN31: CH4, vol % | AO31: 4.9 | AP31: =($A$34)*($AO$34*AO31/100*1000)/($E$24*$B$34) -> 16177.935 | AR31: CH4, vol % | AS31: 0 | AT31: =AS31/100*$AT$34 -> 0
C32: C2+, vol % | D32: 3.5 | E32: =($A$34)*($D$34*D32/100*1000)/($E$24*$B$34) -> 3051.3745 | G32: 14.130909 | H32: =G32*L32 -> 38960.822 | J32: C2+, vol % | K32: 3.3 | L32: =($A$34)*($K$34*K32/100*1000)/($E$24*$B$34) -> 2757.1348 | O32: 7.3660903 | P32: =T32*O32 -> 21287.457 | R32: C2+, vol % | S32: 1 | T32: =($A$34)*($S$34*S32/100*1000)/($E$24*$B$34) -> 2889.9261 | U32: 22.55655 | V32: =T32*U32 -> 65186.764 | Y32: =AVERAGE(Y28,Y30) -> 0.03 | AA32: C2+, vol % | AB32: 0 | AC32: =($A$34)*($AB$34*AB32/100*1000)/($E$24*$B$34) -> 0 | AE32: -31.977801 | AF32: =AC32*AE32 -> 0 | AK32: -16.725299 | AL32: =AK32*AP32 -> 0 | AN32: C2+, vol % | AO32: 0 | AP32: =($A$34)*($AO$34*AO32/100*1000)/($E$24*$B$34) -> 0 | AR32: C2+, vol % | AS32: 0 | AT32: =AS32/100*$AT$34 -> 0
A33: p_0 | B33: T_0 | C33: H2O, vol % | D33: 0 | E33: =($A$34)*($D$34*D33/100*1000)/($E$24*$B$34) -> 0 | G33: 12.671218 | H33: =G33*L33 -> 0 | J33: H2O, vol % | K33: 0 | L33: =($A$34)*($K$34*K33/100*1000)/($E$24*$B$34) -> 0 | O33: 10.374144 | P33: =T33*O33 -> 2140608.4 | R33: H2O, vol % | S33: 71.4 | T33: =($A$34)*($S$34*S33/100*1000)/($E$24*$B$34) -> 206340.72 | U33: 13.380599 | V33: =T33*U33 -> 2760962.5 | AA33: H2O, vol % | AB33: 28.3 | AC33: =($A$34)*($AB$34*AB33/100*1000)/($E$24*$B$34) -> 119364.85 | AE33: -19.716905 | AF33: =AC33*AE33 -> -2353505.3 | AK33: -14.441973 | AL33: =AK33*AP33 -> -7152.2852 | AN33: H2O, vol % | AO33: 0.15 | AP33: =($A$34)*($AO$34*AO33/100*1000)/($E$24*$B$34) -> 495.24292 | AR33: H2O, vol % | AS33: 0 | AT33: =AS33/100*$AT$34 -> 0
A34: 1 | B34: 298 | C34: Quantity, m3 (STP/h) | D34: 2160 | E34: =($A$34)*($D$34*1000)/($E$24*$B$34) -> 87182.128 | J34: Quantity, m3 (STP/h) | K34: 2070 | L34: =($A$34)*($K$34*1000)/($E$24*$B$34) -> 83549.54 | R34: Quantity, m3 (STP/h) | S34: 7160 | T34: =($A$34)*($S$34*1000)/($E$24*$B$34) -> 288992.61 | AA34: Quantity, m3 (STP/h) | AB34: 10450 | AC34: =($A$34)*($AB$34*1000)/($E$24*$B$34) -> 421783.91 | AE34: SUM | AF34: =SUM(AF27:AF33) -> -7486330.1 | AK34: SUM (HXF+HX5) | AL34: =SUM(AL27:AL33) -> -4591920.9 | AN34: Quantity, m3 (STP/h) | AO34: 8180 | AP34: =($A$34)*($AO$34*1000)/($E$24*$B$34) -> 330161.95 | AR34: Quantity, m3 (STP/h) | AS34: 5000.5 | AT34: =($A$34)*($AS$34*1000)/($E$24*$B$34) -> 201830.66
C35: Temperature, °C | D35: 20 | J35: Temperature, °C | K35: 390 | R35: Temperature, °C | S35: 520 | AA35: Temperature, °C | AB35: 850 | AK35: HX5 | AL35: =AL34+H37 -> -3425401.2 | AN35: Temperature, °C | AO35: 20 | AR35: Temperature, °C | AS35: 20
C36: Pressure, MPa | D36: 2 | J36: Pressure, MPa | K36: 1.9 | R36: Pressure, MPa | S36: 1.9 | AA36: Pressure, MPa | AB36: 1.7 | AN36: Pressure, MPa | AO36: 1.6 | AR36: Pressure, MPa | AS36: 1.5
H37: =SUM(H27:H33) -> 1166519.8 | J37: SUM | P37: =SUM(P27:P33) -> 2735098.3 | R37: SUM | V37: =SUM(V27:V33) -> 4573546.5 | X37: =SUM(X27:X28,X30) -> 14325418 | Y37: =-Y32*SUM(P76,AG52) -> 960551.62
Q39: Flue gas balance | S39: Steam balance | U39: Overall
Q40: heat-adding | R40: heat-consuming | S40: heat-adding | T40: heat-consuming | U40: heat-adding | V40: heat-consuming
AA41: Parameter | AB41: Purge gas | AC41: Mole, mol | AD41: Molar heat capacity, kJ/mol | AE41: Vapourisation enthalpy 25°C, kJ/mol | AF41: LHV 25°C, kJ/mol | AG41: Combustion energy, kJ/h | AI41: Temperature increase check
N42: balance closing over 5 and 6 | O42: Purge gas combustion | Q42: =AG52 -> -25807960 | U42: =Q42 -> -25807960 | AA42: H2, vol % | AB42: =AC42/$AC$49*100 -> 32.560964 | AC42: =AP27-AT27-AL61 -> 40479.956 | AF42: 244 | AG42: =AF42*AC42*-1 -> -9877109.2 | AJ42: Reaction | AK42: Molar heat capacity, kJ/mol | AL42: Heat-up energy, kJ/h
N43: balance cloxing over 1 and 2 | O43: Fuel gas combustion | Q43: =P76 -> -6210427.3 | U43: =Q43 -> -6210427.3 | AA43: N2, vol % | AB43: =AC43/$AC$49*100 -> 0.64737568 | AC43: =AP28-AT28-AL62 -> 804.82073 | AD43: =N142 -> 23.100387 | AG43: =AC43*AD43 -> 18591.67 | AI43: Mole CH4, mol | AJ43: =AP29-AC29 -> -27632.295 | AK43: {=N131:N137} -> 2.6457666 | AL43: =AK43*AP27 -> 651654.46
N44: balance closing over HXA | O44: HXA+ | Q44: =R49*-1 -> -4886049.5 | U44: =Q44 -> -4886049.5 | AA44: CO, vol % | AB44: =AC44/$AC$49*100 -> 14.07538 | AC44: =AP29-AT29-AL63 -> 17498.583 | AF44: 283.24 | AG44: =AF44*AC44*-1 -> -4956298.7 | AI44: Reaction enthalpy, kJ/mol | AJ44: =AC141 -> -35.812382 | AK44: 2.4738775 | AL44: =AK44*AP28 -> 2041.9506
...

Sheet SMR, rev. DMR, C-forming, C2H6
B10: Parameter | C10: Feed, 1 | D10: Before desulfurization, 2 | E10: Reformer inlet, 3 | F10: Reformer outlet, 4 | G10: Pressure swing adsorption, 5 | H10: H2 product, 6
B11: H2, vol % | C11: 0 | D11: 4.8 | E11: 1.1 | F11: 51.9 | G11: 74.6 | H11: 99.99 | Q11: Steam export | R11: 4700 | S11: kg/h
B12: N2, vol % | C12: 1 | D12: 1 | E12: 0.3 | F12: 0.2 | G12: 0.25 | H12: 0.01 | R12: 3 | S12: MPa
B13: CO, vol % | C13: 0 | D13: 0 | E13: 0 | F13: 10.7 | G13: 5.3 | H13: 0 | R13: 255 | S13: °C | U13: Off gas
B14: CO2, vol % | C14: 0.5 | D14: 0.5 | E14: 0.1 | F14: 5.1 | G14: 14.8 | H14: 0 | W14: min | X14: max | Y14: average
B15: CH4, vol % | C15: 95 | D15: 90.4 | E15: 26.1 | F15: 3.8 | G15: 4.9 | H15: 0 | U15: Insulation losses | V15: Furnace section | W15: 0.01 | X15: 0.05 | Y15: =AVERAGE(W15:X15) -> 0.03
B16: C2+, vol % | C16: 3.5 | D16: 3.3 | E16: 1 | F16: 0 | G16: 0 | H16: 0 | V16: Convection zone | W16: 0.06 | X16: 0.1 | Y16: =AVERAGE(W16:X16) -> 0.08
B17: H2O, vol % | C17: 0 | D17: 0 | E17: 71.4 | F17: 28.3 | G17: 0.15 | H17: 0 | W17: [Ullmanns, Hydrogen, 2. Production, 266] | X17: [Ullmanns, Hydrogen, 2. Production, 266]
B18: Quantity, m3 (STP/h) | C18: 2160 | D18: 2070 | E18: 7160 | F18: 10450 | G18: 8180 | H18: 5000.5 | P18: SMR steam
B19: Temperature, °C | C19: 20 | D19: 390 | E19: 520 | F19: 850 | G19: 20 | H19: 20 | X19: Water
B20: Pressure, MPa | C20: 2 | D20: 1.9 | E20: 1.9 | F20: 1.7 | G20: 1.6 | H20: 1.5
H26: Parameter | I26: Feed, 1 | L26: Parameter | M26: Before desulfurization, 2 | R26: Parameter | S26: Reformer inlet, 3 | V26: Parameter | W26: Reformer outlet, 4 | AD26: Parameter | AE26: Pressure swing adsorption, 5 | AH26: Parameter | AI26: H2 product, 6
H27: H2, vol % | I27: 0 | L27: H2, vol % | M27: 4.8 | R27: H2, vol % | S27: 1.1 | V27: H2, vol % | W27: 51.9 | AD27: H2, vol % | AE27: 74.6 | AH27: H2, vol % | AI27: 99.99
H28: N2, vol % | I28: 1 | L28: N2, vol % | M28: 1 | R28: N2, vol % | S28: 0.3 | V28: N2, vol % | W28: 0.2 | AD28: N2, vol % | AE28: 0.25 | AH28: N2, vol % | AI28: 0.01
H29: CO, vol % | I29: 0 | L29: CO, vol % | M29: 0 | R29: CO, vol % | S29: 0 | V29: CO, vol % | W29: 10.7 | AD29: CO, vol % | AE29: 5.3 | AH29: CO, vol % | AI29: 0
H30: CO2, vol % | I30: 0.5 | L30: CO2, vol % | M30: 0.5 | R30: CO2, vol % | S30: 0.1 | V30: CO2, vol % | W30: 5.1 | AD30: CO2, vol % | AE30: 14.8 | AH30: CO2, vol % | AI30: 0
H31: CH4, vol % | I31: 95 | L31: CH4, vol % | M31: 90.4 | R31: CH4, vol % | S31: 26.1 | V31: CH4, vol % | W31: 3.8 | AD31: CH4, vol % | AE31: 4.9 | AH31: CH4, vol % | AI31: 0
H32: C2+, vol % | I32: 3.5 | L32: C2+, vol % | M32: 3.3 | R32: C2+, vol % | S32: 1 | V32: C2+, vol % | W32: 0 | AD32: C2+, vol % | AE32: 0 | AH32: C2+, vol % | AI32: 0
H33: H2O, vol % | I33: 0 | L33: H2O, vol % | M33: 0 | R33: H2O, vol % | S33: 71.4 | V33: H2O, vol % | W33: 28.3 | AD33: H2O, vol % | AE33: 0.15 | AH33: H2O, vol % | AI33: 0
H34: Quantity, m3 (STP/h) | I34: 2160 | L34: Quantity, m3 (STP/h) | M34: 2070 | R34: Quantity, m3 (STP/h) | S34: 7160 | T34: =O49 -> 288992.61 | V34: Quantity, m3 (STP/h) | W34: 10450 | X34: =($K$49)*($W$34*1000)/($N$39*$L$49) -> 421783.91 | AD34: Quantity, m3 (STP/h) | AE34: 8180 | AH34: Quantity, m3 (STP/h) | AI34: 5000.5
H35: Temperature, °C | I35: 20 | L35: Temperature, °C | M35: 390 | R35: Temperature, °C | S35: 520 | V35: Temperature, °C | W35: 850 | AD35: Temperature, °C | AE35: 20 | AH35: Temperature, °C | AI35: 20
H36: Pressure, MPa | I36: 2 | L36: Pressure, MPa | M36: 1.9 | R36: Pressure, MPa | S36: 1.9 | V36: Pressure, MPa | W36: 1.7 | AD36: Pressure, MPa | AE36: 1.6 | AH36: Pressure, MPa | AI36: 1.5
N37: Ideal gas | AA37: Ideal gas
N38: n = p*V/(R*T) | AA38: n = p*V/(R*T) | AD38: Delta T
M39: R = | N39: 0.08314 | O39: bar*l/(mol*K) | Z39: R = | AA39: 0.08314 | AB39: bar*l/(mol*K) | AD39: 230 | AE39: K
M41: Parameter | N41: Reformer inlet, 3 | O41: Mole | P41: Molar heat capacity [kJ/(mol K)] | Q41: Heat-up energy [kJ] | S41: Reaction enthalpy [kJ] | T41: Insulation losses [kJ] | Y41: Parameter | Z41: Purge gas | AA41: Mole | AB41: Molar heat capacity 25°C [kJ/(mol K)] | AC41: Vapourisation enthalpy 25°C [kJ/mol] | AD41: LHV 25°C [kJ/mol] | AE41: Combustion energy [kJ]
M42: H2, vol % | N42: 1.1 | O42: =($K$49)*($N$49*N42/100*1000)/($N$39*$L$49) -> 3178.9187 | P42: see below | Q42: =O42*SUM(F100:F430) -> 20051.823 | R42: I | S42: =T93*W104 -> 9891716.8 | Y42: H2, vol % | Z42: =($AE$34*AE27/100-$AI$34*AI27/100-$W$80*W70/100)/$Z$49*100 -> 32.560964 | AA42: =($W$49)*($Z$49*Z42/100*1000)/($AA$39*$X$49) -> 40479.956 | AD42: 244 | AE42: =AD42*AA42*-1 -> -9877109.2
M43: N2, vol % | N43: 0.3 | O43: =($K$49)*($N$49*N43/100*1000)/($N$39*$L$49) -> 866.97783 | P43: see below | Q43: =O43*SUM(G100:G430) -> 9303.7102 | R43: IV | S43: =T90*W109 -> -6610180.4 | Y43: N2, vol % | Z43: =($AE$34*AE28/100-$AI$34*AI28/100-$W$80*W71/100)/$Z$49*100 -> 0.64737568 | AA43: =($W$49)*($Z$49*Z43/100*1000)/($AA$39*$X$49) -> 804.82073 | AE43: neglegible
M44: CO, vol % | N44: 0 | O44: =($K$49)*($N$49*N44/100*1000)/($N$39*$L$49) -> 0 | Q44: 0 | R44: VII | S44: neglected | Y44: CO, vol % | Z44: =($AE$34*AE29/100-$AI$34*AI29/100-$W$80*W72/100)/$Z$49*100 -> 14.07538 | AA44: =($W$49)*($Z$49*Z44/100*1000)/($AA$39*$X$49) -> 17498.583 | AD44: 283.24 | AE44: =AD44*AA44*-1 -> -4956298.7
M45: CO2, vol % | N45: 0.1 | O45: =($K$49)*($N$49*N45/100*1000)/($N$39*$L$49) -> 288.99261 | P45: see below | Q45: =O45*SUM(H100:H430) -> 5134.9963 | R45: VIII | S45: =T92*W118 -> 14393.65 | Y45: CO2, vol % | Z45: =($AE$34*AE30/100-$AI$34*AI30/100-$W$80*W73/100)/$Z$49*100 -> 39.304834 | AA45: =($W$49)*($Z$49*Z45/100*1000)/($AA$39*$X$49) -> 48863.968 | AB45: =H80 -> 0.037122832 | AE45: =AA45*AB45*AD39 -> 417212.84
M46: CH4, vol % | N46: 26.1 | O46: =($K$49)*($N$49*N46/100*1000)/($N$39*$L$49) -> 75427.071 | P46: see below | Q46: =O46*SUM(D100:D430) -> 1744545.8 | Y46: CH4, vol % | Z46: =($AE$34*AE31/100-$AI$34*AI31/100-$W$80*W74/100)/$Z$49*100 -> 13.013087 | AA46: =($W$49)*($Z$49*Z46/100*1000)/($AA$39*$X$49) -> 16177.935 | AD46: 802.34 | AE46: =AD46*AA46*-1 -> -12980205
M47: C2+, vol % | N47: 1 | O47: =($K$49)*($N$49*N47/100*1000)/($N$39*$L$49) -> 2889.9261 | P47: approximation with CH4 values | Q47: =O47*SUM(F100:F430) -> 18228.93 | Y47: C2+, vol % | Z47: =($AE$34*AE32/100-$AI$34*AI32/100-$W$80*W75/100)/$Z$49*100 -> 0 | AA47: =($W$49)*($Z$49*Z47/100*1000)/($AA$39*$X$49) -> 0
M48: H2O, vol % | N48: 71.4 | O48: =($K$49)*($N$49*N48/100*1000)/($N$39*$L$49) -> 206340.72 | P48: see below | Q48: =O48*SUM(E100:E430) -> 36719652 | Y48: H2O, vol % | Z48: =($AE$34*AE33/100-$AI$34*AI33/100-$W$80*W76/100)/$Z$49*100 -> 0.3983598 | AA48: =($W$49)*($Z$49*Z48/100*1000)/($AA$39*$X$49) -> 495.24292 | AC48: 43.99 | AE48: neglegible
K49: 1 | L49: 298 | M49: Quantity, m3 (STP/h) | N49: 7160 | O49: =($K$49)*($N$49*1000)/($N$39*$L$49) -> 288992.61 | W49: 1 | X49: 298 | Y49: Quantity, m3 (STP/h) | Z49: =AE34-AI34-W80 -> 3080.1301
M50: Temperature, °C | N50: 520 | Y50: Temperature, °C | Z50: =AE35 -> 20
M51: Pressure, MPa | N51: 1.9 | Y51: Pressure, MPa | Z51: =AE36 -> 1.6
M52: SUM | Q52: =SUM(Q42:Q48) -> 38516917 | S52: =SUM(S42:S43,S45) -> 3295930.1 | T52: =SUM(Q52:S52)/(1-SUM(Y15:Y16))*SUM(Y15:Y16) -> 5167880 | Y52: SUM | AE52: =SUM(AE42,AE44:AE46) -> -27396400
AC53: https://de.wikipedia.org/wiki/Verdampfungsenthalpie | AD53: https://en.wikipedia.org/wiki/Heat_of_combustion
U58: Fuel gas
U59: Combustion energy [kJ] | V59: =SUM(Q52:T52,AE52)*-1 -> -19584327
...
